ERROR:root:no i szlag trafi³ kaskê ;pp
INFO:WDM:

INFO:WDM:====== WebDriver manager ======
INFO:WDM:Current google-chrome version is 100.0.4896
INFO:WDM:Get LATEST chromedriver version for 100.0.4896 google-chrome
INFO:WDM:Driver [C:\Users\klime\.wdm\drivers\chromedriver\win32\100.0.4896.60\chromedriver.exe] found in cache
ERROR:root:no i szlag trafi³ kaskê ;pp
2022-04-21 13:32:09,595 - __main__ - ERROR - SIema
ERROR:__main__:2022-04-21 13:35:08,241
SIema

ERROR:__main__:2022-04-21 13:36:10,985
SIema

ERROR:__main__:21/04/2022 13:39:17
SIema

ERROR:__main__:21-04-2022 13:44:57 SIema
ERROR:root:no i szlag trafi³ kaskê ;pp
ERROR:root:no i szlag trafi³ kaskê ;pp
ERROR:root:someinfo
ERROR:root:someinfo
WARNING:root:someinfo
DEBUG:root:someinfo

ERROR:database_connection:09-05-2022 18:37:24 <class 'pyodbc.ProgrammingError'>, ('42000', "[42000] [Microsoft][ODBC Driver 17 for SQL Server][SQL Server]The EXECUTE permission was denied on the object 'add_bonus_email', database 'Plemiona', schema 'dbo'. (229) (SQLExecDirectW)"), <traceback object at 0x0000017A69361140>

ERROR:database_connection:09-05-2022 18:42:40 <class 'pyodbc.ProgrammingError'>, ('42000', "[42000] [Microsoft][ODBC Driver 17 for SQL Server][SQL Server]The EXECUTE permission was denied on the object 'add_bonus_email', database 'Plemiona', schema 'dbo'. (229) (SQLExecDirectW)"), <traceback object at 0x00000293CE7D9C40>

ERROR:database_connection:09-05-2022 18:42:59 <class 'pyodbc.ProgrammingError'>, ('42000', "[42000] [Microsoft][ODBC Driver 17 for SQL Server][SQL Server]The EXECUTE permission was denied on the object 'add_bonus_email', database 'Plemiona', schema 'dbo'. (229) (SQLExecDirectW)"), <traceback object at 0x00000293CFDF2E80>

ERROR:database_connection:09-05-2022 18:47:02 <class 'pyodbc.ProgrammingError'>, ('42000', "[42000] [Microsoft][ODBC Driver 17 for SQL Server][SQL Server]The EXECUTE permission was denied on the object 'add_bonus_email', database 'Plemiona', schema 'dbo'. (229) (SQLExecDirectW)"), <traceback object at 0x00000293D076E5C0>

ERROR:database_connection:09-05-2022 18:47:09 <class 'pyodbc.ProgrammingError'>, ('42000', "[42000] [Microsoft][ODBC Driver 17 for SQL Server][SQL Server]The EXECUTE permission was denied on the object 'add_bonus_email', database 'Plemiona', schema 'dbo'. (229) (SQLExecDirectW)"), <traceback object at 0x00000293D076F1C0>

ERROR:database_connection:09-05-2022 18:47:16 <class 'pyodbc.ProgrammingError'>, ('42000', "[42000] [Microsoft][ODBC Driver 17 for SQL Server][SQL Server]The EXECUTE permission was denied on the object 'add_bonus_email', database 'Plemiona', schema 'dbo'. (229) (SQLExecDirectW)"), <traceback object at 0x00000293D0DB0180>

ERROR:database_connection:09-05-2022 18:47:21 <class 'pyodbc.ProgrammingError'>, ('42000', "[42000] [Microsoft][ODBC Driver 17 for SQL Server][SQL Server]The EXECUTE permission was denied on the object 'add_bonus_email', database 'Plemiona', schema 'dbo'. (229) (SQLExecDirectW)"), <traceback object at 0x00000293D0DB1180>

ERROR:database_connection:09-05-2022 18:47:29 <class 'pyodbc.ProgrammingError'>, ('42000', "[42000] [Microsoft][ODBC Driver 17 for SQL Server][SQL Server]The EXECUTE permission was denied on the object 'add_bonus_email', database 'Plemiona', schema 'dbo'. (229) (SQLExecDirectW)"), <traceback object at 0x00000293D0DB17C0>

ERROR:database_connection:09-05-2022 18:47:39 <class 'pyodbc.ProgrammingError'>, ('42000', "[42000] [Microsoft][ODBC Driver 17 for SQL Server][SQL Server]The EXECUTE permission was denied on the object 'add_bonus_email', database 'Plemiona', schema 'dbo'. (229) (SQLExecDirectW)"), <traceback object at 0x00000293D0DB2C80>

ERROR:database_connection:09-05-2022 19:06:49 <class 'pyodbc.ProgrammingError'>, ('42000', "[42000] [Microsoft][ODBC Driver 17 for SQL Server][SQL Server]The EXECUTE permission was denied on the object 'add_bonus_email', database 'Plemiona', schema 'dbo'. (229) (SQLExecDirectW)"), <traceback object at 0x00000293D0DB3B40>

ERROR:database_connection:09-05-2022 19:06:55 <class 'pyodbc.ProgrammingError'>, ('42000', "[42000] [Microsoft][ODBC Driver 17 for SQL Server][SQL Server]The EXECUTE permission was denied on the object 'add_bonus_email', database 'Plemiona', schema 'dbo'. (229) (SQLExecDirectW)"), <traceback object at 0x00000293D01CCAC0>

ERROR:database_connection:09-05-2022 19:07:26 <class 'pyodbc.ProgrammingError'>, ('42000', "[42000] [Microsoft][ODBC Driver 17 for SQL Server][SQL Server]The EXECUTE permission was denied on the object 'add_bonus_email', database 'Plemiona', schema 'dbo'. (229) (SQLExecDirectW)"), <traceback object at 0x00000293CEC06640>

ERROR:database_connection:09-05-2022 19:07:36 <class 'pyodbc.ProgrammingError'>, ('42000', "[42000] [Microsoft][ODBC Driver 17 for SQL Server][SQL Server]The EXECUTE permission was denied on the object 'add_bonus_email', database 'Plemiona', schema 'dbo'. (229) (SQLExecDirectW)"), <traceback object at 0x00000293D01CE880>

ERROR:database_connection:09-05-2022 19:07:50 <class 'pyodbc.ProgrammingError'>, ('42000', "[42000] [Microsoft][ODBC Driver 17 for SQL Server][SQL Server]The EXECUTE permission was denied on the object 'add_bonus_email', database 'Plemiona', schema 'dbo'. (229) (SQLExecDirectW)"), <traceback object at 0x00000293D01CF300>

ERROR:database_connection:09-05-2022 19:08:42 <class 'pyodbc.ProgrammingError'>, ('42000', "[42000] [Microsoft][ODBC Driver 17 for SQL Server][SQL Server]Incorrect syntax near 'klimekop6'. (102) (SQLExecDirectW)"), <traceback object at 0x00000293D076E980>

ERROR:database_connection:09-05-2022 19:08:58 <class 'pyodbc.ProgrammingError'>, ('42000', "[42000] [Microsoft][ODBC Driver 17 for SQL Server][SQL Server]Incorrect syntax near 'klimekop6'. (102) (SQLExecDirectW)"), <traceback object at 0x00000293D0DC4E40>

ERROR:database_connection:09-05-2022 19:09:08 <class 'pyodbc.ProgrammingError'>, ('42000', "[42000] [Microsoft][ODBC Driver 17 for SQL Server][SQL Server]The EXECUTE permission was denied on the object 'add_bonus_email', database 'Plemiona', schema 'dbo'. (229) (SQLExecDirectW)"), <traceback object at 0x00000293D01CFD80>

ERROR:database_connection:09-05-2022 19:11:56 <class 'pyodbc.ProgrammingError'>, ('42000', "[42000] [Microsoft][ODBC Driver 17 for SQL Server][SQL Server]The EXECUTE permission was denied on the object 'add_bonus_email', database 'Plemiona', schema 'dbo'. (229) (SQLExecDirectW)"), <traceback object at 0x00000293D076D400>

ERROR:bot_functions:11-05-2022 20:21:02 

bot_functions -> log_in error raised

chrome://new-tab-page/

Traceback (most recent call last):
  File "c:\Users\klime\VS Code\selenium_chrome\bot_functions.py", line 1024, in log_in
    f"https://www.{settings['game_url']}/page/play/{settings['server_world']}"
KeyError: 'server_world'
-----------------------------------------------------------------------------------


ERROR:database_connection:12-05-2022 13:27:59 <class 'pyodbc.ProgrammingError'>, ('42000', "[42000] [Microsoft][ODBC Driver 17 for SQL Server][SQL Server]Incorrect syntax near 'invited_by'. (102) (SQLExecDirectW)"), <traceback object at 0x0000028BCE203980>

ERROR:__main__:17-05-2022 14:25:58 Called empty settings['scheduler']['ready_schedule']
Stack (most recent call last):
  File "C:\Users\klime\AppData\Local\Programs\Python\Python310\lib\runpy.py", line 196, in _run_module_as_main
    return _run_code(code, main_globals, None,
  File "C:\Users\klime\AppData\Local\Programs\Python\Python310\lib\runpy.py", line 86, in _run_code
    exec(code, run_globals)
  File "c:\Users\klime\.vscode\extensions\ms-python.python-2022.6.2\pythonFiles\lib\python\debugpy\__main__.py", line 45, in <module>
    cli.main()
  File "c:\Users\klime\.vscode\extensions\ms-python.python-2022.6.2\pythonFiles\lib\python\debugpy/..\debugpy\server\cli.py", line 444, in main
    run()
  File "c:\Users\klime\.vscode\extensions\ms-python.python-2022.6.2\pythonFiles\lib\python\debugpy/..\debugpy\server\cli.py", line 285, in run_file
    runpy.run_path(target_as_str, run_name=compat.force_str("__main__"))
  File "C:\Users\klime\AppData\Local\Programs\Python\Python310\lib\runpy.py", line 269, in run_path
    return _run_module_code(code, init_globals, run_name,
  File "C:\Users\klime\AppData\Local\Programs\Python\Python310\lib\runpy.py", line 96, in _run_module_code
    _run_code(code, mod_globals, init_globals,
  File "C:\Users\klime\AppData\Local\Programs\Python\Python310\lib\runpy.py", line 86, in _run_code
    exec(code, run_globals)
  File "c:\Users\klime\VS Code\selenium_chrome\bot_main.py", line 4097, in <module>
    main()
  File "c:\Users\klime\VS Code\selenium_chrome\bot_main.py", line 4090, in main
    main_window.master.mainloop()
  File "C:\Users\klime\AppData\Local\Programs\Python\Python310\lib\tkinter\__init__.py", line 1458, in mainloop
    self.tk.mainloop(n)
  File "C:\Users\klime\AppData\Local\Programs\Python\Python310\lib\tkinter\__init__.py", line 1921, in __call__
    return self.func(*args)
  File "c:\Users\klime\VS Code\selenium_chrome\log_in_window.py", line 134, in <lambda>
    lambda _: self.log_in(main_window, settings),
  File "c:\Users\klime\VS Code\selenium_chrome\log_in_window.py", line 217, in log_in
    self.after_correct_log_in(

ERROR:__main__:17-05-2022 14:27:08 Called empty settings['scheduler']['ready_schedule']
Stack (most recent call last):
  File "C:\Users\klime\AppData\Local\Programs\Python\Python310\lib\runpy.py", line 196, in _run_module_as_main
    return _run_code(code, main_globals, None,
  File "C:\Users\klime\AppData\Local\Programs\Python\Python310\lib\runpy.py", line 86, in _run_code
    exec(code, run_globals)
  File "c:\Users\klime\.vscode\extensions\ms-python.python-2022.6.2\pythonFiles\lib\python\debugpy\__main__.py", line 45, in <module>
    cli.main()
  File "c:\Users\klime\.vscode\extensions\ms-python.python-2022.6.2\pythonFiles\lib\python\debugpy/..\debugpy\server\cli.py", line 444, in main
    run()
  File "c:\Users\klime\.vscode\extensions\ms-python.python-2022.6.2\pythonFiles\lib\python\debugpy/..\debugpy\server\cli.py", line 285, in run_file
    runpy.run_path(target_as_str, run_name=compat.force_str("__main__"))
  File "C:\Users\klime\AppData\Local\Programs\Python\Python310\lib\runpy.py", line 269, in run_path
    return _run_module_code(code, init_globals, run_name,
  File "C:\Users\klime\AppData\Local\Programs\Python\Python310\lib\runpy.py", line 96, in _run_module_code
    _run_code(code, mod_globals, init_globals,
  File "C:\Users\klime\AppData\Local\Programs\Python\Python310\lib\runpy.py", line 86, in _run_code
    exec(code, run_globals)
  File "c:\Users\klime\VS Code\selenium_chrome\bot_main.py", line 4097, in <module>
    main()
  File "c:\Users\klime\VS Code\selenium_chrome\bot_main.py", line 4090, in main
    main_window.master.mainloop()
  File "C:\Users\klime\AppData\Local\Programs\Python\Python310\lib\tkinter\__init__.py", line 1458, in mainloop
    self.tk.mainloop(n)
  File "C:\Users\klime\AppData\Local\Programs\Python\Python310\lib\tkinter\__init__.py", line 1921, in __call__
    return self.func(*args)
  File "c:\Users\klime\VS Code\selenium_chrome\log_in_window.py", line 134, in <lambda>
    lambda _: self.log_in(main_window, settings),
  File "c:\Users\klime\VS Code\selenium_chrome\log_in_window.py", line 217, in log_in
    self.after_correct_log_in(
  File "c:\Users\klime\VS Code\selenium_chrome\log_in_window.py", line 178, in after_correct_log_in
    main_window.load_after_log_in(settings=settings)
  File "c:\Users\klime\VS Code\selenium_chrome\bot_main.py", line 2949, in load_after_log_in
    logger.error(

ERROR:__main__:17-05-2022 14:31:21 Called empty settings['scheduler']['ready_schedule']
['  File "c:\\Users\\klime\\VS Code\\selenium_chrome\\log_in_window.py", line 217, in log_in\n    self.after_correct_log_in(\n', '  File "c:\\Users\\klime\\VS Code\\selenium_chrome\\log_in_window.py", line 178, in after_correct_log_in\n    main_window.load_after_log_in(settings=settings)\n', '  File "c:\\Users\\klime\\VS Code\\selenium_chrome\\bot_main.py", line 2942, in load_after_log_in\n    f"Called empty settings[\'scheduler\'][\'ready_schedule\']\\n{traceback.format_stack(limit=3)}"\n']

ERROR:__main__:17-05-2022 14:33:57 Called empty settings['scheduler']['ready_schedule']
  File "c:\Users\klime\VS Code\selenium_chrome\log_in_window.py", line 217, in log_in
    self.after_correct_log_in(
  File "c:\Users\klime\VS Code\selenium_chrome\log_in_window.py", line 178, in after_correct_log_in
    main_window.load_after_log_in(settings=settings)
  File "c:\Users\klime\VS Code\selenium_chrome\bot_main.py", line 2951, in load_after_log_in
    stack_message += "".join(line for line in traceback.format_stack(limit=3))


ERROR:decorators:18-05-2022 13:30:00 
Traceback (most recent call last):
  File "c:\Users\klime\VS Code\selenium_chrome\decorators.py", line 19, in wrapper
    func(*args, **kwargs)
  File "c:\Users\klime\VS Code\selenium_chrome\bot_main.py", line 3129, in run
    ].get() == "0" and int(self.entries_content["check_incoming_attacks"].get()):
KeyError: 'check_incoming_attacks'


ERROR:decorators:18-05-2022 13:31:06 
Traceback (most recent call last):
  File "c:\Users\klime\VS Code\selenium_chrome\decorators.py", line 19, in wrapper
    func(*args, **kwargs)
  File "c:\Users\klime\VS Code\selenium_chrome\bot_main.py", line 3129, in run
    ].get() == "0" and int(self.entries_content["check_incoming_attacks"].get()):
KeyError: 'check_incoming_attacks'


ERROR:decorators:18-05-2022 13:31:14 
Traceback (most recent call last):
  File "c:\Users\klime\VS Code\selenium_chrome\decorators.py", line 19, in wrapper
    func(*args, **kwargs)
  File "c:\Users\klime\VS Code\selenium_chrome\bot_main.py", line 3129, in run
    ].get() == "0" and int(self.entries_content["check_incoming_attacks"].get()):
KeyError: 'check_incoming_attacks'


ERROR:bot_functions:14-06-2022 13:15:42 

unwanted_page_content -> else(uknown error)

https://pl173.plemiona.pl/game.php?village=44235&screen=info_player&mode=daily_bonus

Traceback (most recent call last):
  File "c:\Users\klime\VS Code\selenium_chrome\bot_main.py", line 3426, in run
    bot_functions.attacks_labels(
  File "c:\Users\klime\VS Code\selenium_chrome\bot_functions.py", line 50, in attacks_labels
    WebDriverWait(driver, 10).until(
  File "c:\Users\klime\VS Code\selenium_chrome\.venv_tribal_wars\lib\site-packages\selenium\webdriver\support\wait.py", line 89, in until
    raise TimeoutException(message, screen, stacktrace)
selenium.common.exceptions.TimeoutException: Message: 

-----------------------------------------------------------------------------------


ERROR:bot_functions:14-06-2022 14:32:53 

unwanted_page_content -> else(uknown error)

https://pl173.plemiona.pl/game.php?village=44235&screen=info_player&mode=daily_bonus

Traceback (most recent call last):
  File "c:\Users\klime\VS Code\selenium_chrome\bot_main.py", line 3426, in run
    bot_functions.attacks_labels(
  File "c:\Users\klime\VS Code\selenium_chrome\bot_functions.py", line 50, in attacks_labels
    WebDriverWait(driver, 10).until(
  File "c:\Users\klime\VS Code\selenium_chrome\.venv_tribal_wars\lib\site-packages\selenium\webdriver\support\wait.py", line 89, in until
    raise TimeoutException(message, screen, stacktrace)
selenium.common.exceptions.TimeoutException: Message: 

-----------------------------------------------------------------------------------


ERROR:bot_functions:14-06-2022 14:34:30 

unwanted_page_content -> else(uknown error)

https://pl173.plemiona.pl/game.php?village=44235&screen=info_player&mode=daily_bonus

Traceback (most recent call last):
  File "c:\Users\klime\VS Code\selenium_chrome\bot_main.py", line 3426, in run
    bot_functions.attacks_labels(
  File "c:\Users\klime\VS Code\selenium_chrome\bot_functions.py", line 50, in attacks_labels
    WebDriverWait(driver, 5).until(
  File "c:\Users\klime\VS Code\selenium_chrome\.venv_tribal_wars\lib\site-packages\selenium\webdriver\support\wait.py", line 89, in until
    raise TimeoutException(message, screen, stacktrace)
selenium.common.exceptions.TimeoutException: Message: 

-----------------------------------------------------------------------------------


ERROR:bot_functions:14-06-2022 14:35:39 

unwanted_page_content -> else(uknown error)

https://pl173.plemiona.pl/game.php?village=44235&screen=info_player&mode=daily_bonus

Traceback (most recent call last):
  File "c:\Users\klime\VS Code\selenium_chrome\bot_main.py", line 3426, in run
    bot_functions.attacks_labels(
  File "c:\Users\klime\VS Code\selenium_chrome\bot_functions.py", line 50, in attacks_labels
    WebDriverWait(driver, 5).until(
  File "c:\Users\klime\VS Code\selenium_chrome\.venv_tribal_wars\lib\site-packages\selenium\webdriver\support\wait.py", line 89, in until
    raise TimeoutException(message, screen, stacktrace)
selenium.common.exceptions.TimeoutException: Message: 

-----------------------------------------------------------------------------------


ERROR:bot_functions:23-06-2022 01:26:16 

unwanted_page_content -> else(uknown error)

https://pl173.plemiona.pl/game.php?village=24227&screen=place&try=confirm

Traceback (most recent call last):
  File "c:\Users\klime\VS Code\selenium_chrome\bot_main.py", line 3586, in run
    ) = bot_functions.send_troops(self.driver, _settings)
  File "c:\Users\klime\VS Code\selenium_chrome\bot_functions.py", line 2070, in send_troops
    Keys.chord(Keys.CONTROL, "a", Keys.DELETE)
AttributeError: type object 'Keys' has no attribute 'chord'
-----------------------------------------------------------------------------------

